Workbook

Sheet Méthodologie
A1: Valorisation par somme des parties (SOTP) : méthode et hypothèses retenues
A3: Société : Eiffage SA
A4: Objectif : estimer la valeur d'une action Eiffage SA
A5: Méthode : valorisation de chaque activité par DCF, puis comparaison avec les multiples de sociétés cotées comparables, les objectifs de cours des analystes et le cours de bourse.
A6: Date de valorisation : 09/10/2026
A7: Exercice de référence: 2025
A8: Notes : flux considérés en fin d’année. Montants exprimés en M€, sauf indication contraire.
A9: Ce classeur est un exercice académique de valorisation
A11: Sources :DEU Eiffage 2021 à 2025, comptes consolidés d’APRR 2025, rapports annuels 2025 de VINCI, Bouygues, HOCHTIEF, STRABAG, Skanska et Ferrovial. Les hypothèses de marché s’appuient sur les données de Damodaran (bêtas européens de janvier 2026, prime de risque pays de juillet 2026 et croissance attendue), le taux des OAT françaises à 10 ans et le cours de l’action Eiffage sur Boursorama. Ideal Investisseurs pour le consensus des analystes.
A12: Liens
A13: Eiffage, DEU 2025 à 2021
A14: APRR, comptes consolidés 2025
... A27: Feuille
A28: Données | C28: Tous les chiffres issus des documents officiels
A29: Hypothèses | C29: Hypothèses communes (taux sans risque, prime de risque, impôts, cours, dette nette, participations)
A30: Travaux / Eiffarie / Autres concessions | C30: Un DCF par bloc
A31: SOTP | C31: Somme des parties
A32: Multiples | C32: Multiples des pairs (Q1, médiane, Q3) appliqués à Eiffage.
A33: Sensibilité | C33: Sensibilité de la valeur par action selon le WACC et la croissance à l’infini g
A34: Football field | C34: Synthèse graphique des fourchettes de valeur par méthode.
A36: 2. Pourquoi une somme des parties
A37: Les trois blocs sont valorisés séparément, car ils présentent des niveaux de risque et des durées d’exploitation différents. Travaux (Construction, Infrastructures, Énergie Systèmes) est traité comme une activité pérenne. Sa valorisation inclut une valeur terminale calculée selon la méthode de Gordon-Shapiro. Financière Eiffarie (APRR, AREA et Aliaé) regroupe des concessions qui arrivent à échéance en 2035 et 2036. Les ouvrages sont ensuite remis à l’État sans indemnité. Seuls les flux prévisionnels jusqu’à la fin des concessions sont donc retenus, sans valeur terminale. Les autres concessions (A'liénor, Adelac, viaduc de Millau, aéroport de Toulouse-Blagnac, etc.) sont projetées jusqu’en 2040. Les flux au-delà de cette date sont estimés à partir d’une annuité croissante au taux g (0,9 %), jusqu’à une échéance moyenne fixée à 2060. Un DCF unique avec un seul WACC ne permettrait pas de refléter correctement les différences entre ces activités. Une valorisation par bloc est donc plus adaptée.
A39: 3. Formules et conventions
A40: Notion | C40: Formule et explication
A41: FCFF | C41: NOPAT + dotations - (capex + loyers) + encaissement de BFR. NOPAT = EBIT × (1 - impôt). Les loyers (IFRS 16) sont déduits du FCFF : la dette de location est donc exclue de la dette nette (8 548 M€) ; elle n’est incluse (9 905 M€) que pour les multiples, appliqués à un EBITDA avant loyers.
A42: Coût des fonds propres | C42: CAPM : Ke = Rf + βL × prime de risque.
A43: Bêta (Hamada) | C43: βL = βu × (1 + (1 - t) × D/E). Le bêta désendetté βu des comparables est ré-endetté avec la structure financière cible
A44: WACC | C44: E/V × Ke + (1 - E/V) × Kd × (1 - t), avec E/V = 1/(1 + D/E) et Kd = taux sans risque + spread de crédit.
A45: D/E d’Eiffarie (itéré) | C45: D/E = dette nette / valeur des capitaux propres du DCF, qui dépend elle-même du WACC
A46: Valeur terminale (Travaux) | C46: FCFF terminal × (1 + g) / (WACC - g), avec FCFF terminal = NOPAT de la dernière année (capex = dotations, BFR neutre), actualisée au facteur de la dernière année.
A47: Concession à durée finie | C47: Aucune valeur terminale. Autres concessions après 2040 : annuité croissante au taux g sur n années, actualisée : FCFF × (1 + g) / (WACC - g) × [1 - ((1 + g)/(1 + WACC))^n].
A48: De la VE aux capitaux propres | C48: Valeur d’entreprise - dette nette = capitaux propres à 100 % ; - intérêts minoritaires = part du Groupe. Pour les concessions : capitaux propres = MAX(VE - dette ; 0), car leur dette est sans recours (les actionnaires ne perdent pas plus que leur mise). Ce plancher ne joue pas ici.
A49: Intérêts minoritaires | C49: Concessions : (1 - % détenu) × capitaux propres. Travaux : résultat revenant aux minoritaires hors Eiffarie, Adelac et Toulouse × PER de marché (approximation, car le DEU ne détaille que ces trois sociétés).
A50: Sociétés mises en équivalence (MEE) | C50: Participations non consolidées ligne à ligne (ex. Getlink 27,66 %). Leur EBITDA n’est pas dans celui du Groupe : on les retire de la VE de marché pour les multiples, et on les ajoute aux capitaux propres du SOTP. Valeur de marché pour Getlink (cotée), valeur comptable pour les autres.
A51: Coûts de holding | C51: EBITDA de la holding (-22 M€) capitalisé au multiple VE/EBITDA des Travaux et déduit.
A53: 4. Hypothèses : valeur, justification, source
A54: Hypothèse | B54: Valeur | C54: Justification | D54: Source / sensibilité
A55: Taux sans risque | B55: =Hypothèses!B5 -> 0.04 | C55: Rendement de l'OAT 10 ans, lissé sur 9 mois pour atténuer la volatilité du jour. | D55: Banque de France / AFT.
A56: Prime de risque du marché | B56: =Hypothèses!B6 -> 0.0494 | C56: Prime de risque pays de la France (actions). | D56: Damodaran, juillet 2026.
A57: Taux d'impôt Travaux / autres concessions | B57: =Hypothèses!B7 -> 0.268 | C57: Moyenne du taux effectif Eiffage 2021-2023 : plus représentative que l'année 2025 pour les Travaux. | D57: DEU Eiffage 2021 à 2023.
...

Sheet Données
A1: DONNEES, SOURCES : DOCUMENTS OFFICIELS
A3: à noter que APRR est utilisé pour désigner FINANCIERE EIFFARIE détenu à 52,5% par le groupe et constitué de APRR, AREA et Aliaé
A4: Donnée | B4: Valeur | C4: Source
A5: DEU 2025 note 4.1 (information sectorielle) : résultat opérationnel courant (ROC)
A6: ROC Construction | B6: 152 | C6: DEU 2025, note 4.1, tableau « Par secteur d’activité »
A7: ROC Infrastructures | B7: 321 | C7: idem
A8: ROC Énergie Systèmes | B8: 500 | C8: idem
A9: ROC Concessions | B9: 1712 | C9: idem
A10: ROC Holding | B10: -82 | C10: idem
A11: ROC Groupe | B11: =SUM(B6,B7,B8,B9,B10) -> 2603 | C11: Calcul pour contrôle
A12: DEU 2025 note 4.1 : dotations aux amortissements et provisions (valeurs positives)
A13: Dotations Construction | B13: 68 | C13: DEU 2025, note 4.1, ligne « Dont dotations aux amort. et aux provisions »
A14: Dotations Infrastructures | B14: 455 | C14: idem
A15: Dotations Énergie Systèmes | B15: 257 | C15: idem
A16: Dotations Concessions | B16: 951 | C16: idem (inclut les amortissements liés à l’acquisition d’APRR)
A17: Dotations Holding | B17: 60 | C17: idem
A18: Dotations Groupe | B18: =SUM(B13,B14,B15,B16,B17) -> 1791 | C18: Calcul pour contrôle
A19: EBITDA Groupe = ROC + dotations | B19: =$B$11+$B$18 -> 4394 | C19: Calcul pour contrôle
A20: Résultat opérationnel Groupe (EBIT) | B20: 2545 | C20: DEU 2025, compte de résultat consolidé
A21: DEU 2025 chiffre d’affaires hors IFRIC 12 (note 5.1)
A22: CA Construction | B22: 4091 | C22: DEU 2025, note 5.1
A23: CA Infrastructures | B23: 9187 | C23: idem
A24: CA Énergie Systèmes | B24: 8057 | C24: idem
A25: CA Travaux | B25: =$B$22+$B$23+$B$24 -> 21335 | C25: Calcul pour contrôle
A26: CA Concessions | B26: 3978 | C26: DEU 2025, note 5.1 (hors IFRIC 12)
A27: CA Groupe | B27: =$B$25+$B$26 -> 25313 | C27: Calcul pour contrôle
A28: CA APRR-AREA publié dans le DEU | B28: 3183 | C28: DEU 2025, note 5.1, ligne APRR-AREA
A29: CA Aliaé | B29: 56.7 | C29: DEU 2025, p.225
A30: DEU 2025 dette nette, intérêts minoritaires, MEE, actions
A31: Passifs financiers Financière Eiffarie | B31: 8965 | C31: DEU 2025, note 7.2
A32: Trésorerie Financière Eiffarie | B32: 1834 | C32: DEU 2025, note 7.2
A33: Dette financière nette de TOUTES les concessions (hors loyers) | B33: 10076 | C33: DEU 2025, rapport de gestion
A34: Dette nette Travaux (négatif donc trésorerie nette) | B34: -1528 | C34: DEU 2025 (« 1 528 millions d’euros de trésorerie positive nette »)
A35: Dette nette Groupe y compris dettes de location (IFRS 16) | B35: 9905 | C35: DEU 2025
A36: Résultat net revenant aux minoritaires (Groupe) | B36: 445 | C36: DEU 2025, compte de résultat consolidé
A37: dont Financière Eiffarie | B37: 391 | C37: DEU 2025, note 7.2 (tableau « Informations financières à 100 % résumées »)
A38: dont Adelac | B38: 9 | C38: idem
A39: dont Toulouse-Blagnac | B39: -4 | C39: idem
A40: % détenu par les minoritaires dans Financière Eiffarie | B40: 0.475 | C40: DEU 2025, note 7.2 vs pourcentage Eiffarie = 52,5%
A41: % de Getlink détenu par Eiffage | B41: 0.2766 | C41: DEU 2025, note 6.3
...

Sheet Hypothèses
A1: Hypothèses communes
A2: Bleu = donnée saisie / hypothèse ; noir = formule ; vert = lien vers un autre onglet
A3: M€ sauf mention et Base 2025
A4: HYPOTHESES ET INPUTS | B4: Valeur | C4: Source
A5: Taux sans risque (Rf) | B5: 0.04 | C5: OAT 10 ans, moyenne sur 9 mois
A6: Prime de risque du marché | B6: 0.0494 | C6: Damodaran, juillet 2026, France
A7: Taux d'impôt (Travaux et autres concessions) | B7: 0.268 | C7: Moyenne du taux d'impôt effectif Eiffage 2021-2023 (DEU), représentative de la charge d'impôt des Travaux
A8: Taux d'impôt Financière Eiffarie | B8: 0.291 | C8: Moyenne 5 ans (taux légal 25,83 % + surtaxes)
A9: Cours (€) | B9: 98.72 | C9: Boursorama, 09/10/2026
A10: Nombre d'actions (millions) | B10: =(Données!$B$45-Données!$B$46)/1000000 -> 95.081744 | C10: 98 000 000 - 2 918 256 d'autocontrôle
A11: Capitalisation (M€) | B11: =B9*B10 -> 9386.4698
A12: BPA dilué 2025 (€) | B12: =Données!$B$47 -> 10.7 | C12: Résultat net part du Groupe / nombre moyen d'actions APRÈS dilution (actions gratuites). DEU 2025 note 7.4
A13: PER de marché | B13: =B9/B12 -> 9.2261682
A14: Dette nette Travaux (trésorerie nette = négatif) | B14: =Données!$B$34 -> -1528 | C14: DEU 2025, rapport de gestion : trésorerie nette hors concessions (1 528 M€)
A15: Dette nette Financière Eiffarie | B15: =Données!$B$31-Données!$B$32 -> 7131 | C15: DEU 2025 note 7.2 : passifs financiers 8 965 - trésorerie 1 834
A16: Dette nette autres concessions | B16: =Données!$B$33-B15 -> 2945 | C16: Dette nette de toutes les concessions (10 076, DEU) - Eiffarie = résiduel
A17: % de détention Financière Eiffarie | B17: =1-Données!$B$40 -> 0.525 | C17: DEU 2025 : 52,5 % de Financière Eiffarie
A18: % de détention autres concessions | B18: 0.9 | C18: Hypothèse simplificatrice : portefeuille mêlant plusieurs participations de 100 %, et certaines autour de 50 %
A19: Résultat des minoritaires hors concessions (Travaux) | B19: =Données!$B$36-Données!$B$37-Données!$B$38-(Données!$B$39) -> 49 | C19: 445 - 391 (Eiffarie) - 9 (Adelac) - (-4) (Toulouse), DEU note 7.2. Approximation : le DEU ne détaille que ces trois sociétés ainsi le résidu contient possiblement d'autres minoritaires
A20: Participations MEE (Getlink au marché) | B20: =Données!$B$41*Données!$B$42+(Données!$B$43-Données!$B$44) -> 3093.9162 | C20: Getlink coté : 27,66 % × capitalisation (valeur de marché) ; autres MEE non cotées (243 M€) : valeur comptable
A21: EBITDA holding 2025 | B21: =Données!$B$10+Données!$B$17 -> -22 | C21: DEU 2025 note 4 : ROC holding - 82 + dotations 60
A23: Spread de crédit (Kd = Rf + spread)
A24: Spread Travaux | B24: 0.01 | C24: Sans impact car D/E = 0 (trésorerie nette)
A25: Spread Financière Eiffarie | B25: 0.006 | C25: Hypothèse : APRR est notée A (Fitch) / A- (S&P) (DEU 2025), donc écart faible au taux sans risque. Impact limité : ±0,5 pt sur les spreads = ±2 €/action (≈1 %)
A26: Spread autres concessions | B26: 0.008 | C26: Hypothèse : concessions non notées, soit +0,2 pt par rapport à Eiffarie. Impact limité : ±0,5 pt = ±2 €/action (≈1 %)

Sheet SOTP
A1: SOTP
A3: M€ | B3: Travaux | C3: Eiffarie (APRR-AREA-Aliaé) | D3: Autres concessions | E3: Total
A4: EBITDA 2025 | B4: =Travaux!B26 -> 1753 | C4: ='Eiffarie (APRR-AREA-Aliaé)'!B27 -> 2283 | D4: ='Autres concessions'!B26 -> 380 | E4: =SUM(B4:D4) -> 4416
A5: Valeur d'entreprise (DCF) | B5: =Travaux!B46 -> 8026.1396 | C5: ='Eiffarie (APRR-AREA-Aliaé)'!B43 -> 13021.946 | D5: ='Autres concessions'!B46 -> 4856.405 | E5: =SUM(B5:D5) -> 25904.49
A6: VE / EBITDA 2025 | B6: =B5/B4 -> 4.5785166 | C6: =C5/C4 -> 5.7038745 | D6: =D5/D4 -> 12.780013 | E6: =E5/E4 -> 5.866053
A7: WACC | B7: =Travaux!B13 -> 0.07952 | C7: ='Eiffarie (APRR-AREA-Aliaé)'!B13 -> 0.055888681 | D7: ='Autres concessions'!B13 -> 0.060097421
A8: – Dette nette de la partie | B8: =Hypothèses!B14 -> -1528 | C8: =Hypothèses!B15 -> 7131 | D8: =Hypothèses!B16 -> 2945 | E8: =SUM(B8:D8) -> 8548
A9: Valeur des capitaux propres à 100 % | B9: =B5-B8 -> 9554.1396 | C9: =C5-C8 -> 5890.9456 | D9: =D5-D8 -> 1911.405 | E9: =SUM(B9:D9) -> 17356.49
A10: % détenu par Eiffage | C10: =Hypothèses!B17 -> 0.525 | D10: =Hypothèses!B18 -> 0.9
A11: – Intérêts minoritaires | B11: =Hypothèses!B19*Hypothèses!B13 -> 452.08224 | C11: =(1-C10)*MAX(C9,0) -> 2798.1991 | D11: =(1-D10)*MAX(D9,0) -> 191.1405 | E11: =SUM(B11:D11) -> 3441.4219 | F11: Travaux : résultat des minoritaires × PER de marché ; concessions : (1 - % détenu) × capitaux propres
A12: Valeur part du Groupe | B12: =B9-B11 -> 9102.0573 | C12: =MAX(C9,0)-C11 -> 3092.7464 | D12: =MAX(D9,0)-D11 -> 1720.2645 | E12: =SUM(B12:D12) -> 13915.068 | F12: Plancher à 0 pour les concessions : dette sans recours (les actionnaires ne perdent pas plus que leur mise)
A13: + Participations mises en équivalence (Getlink au marché) | E13: =Hypothèses!B20 -> 3093.9162
A14: – Coûts de holding capitalisés (au multiple des Travaux) | E14: =-Hypothèses!B21*B6 -> 100.72736
A15: Valeur des capitaux propres part du Groupe | E15: =E12+E13-E14 -> 16908.257
A16: Nombre d'actions (millions) | E16: =Hypothèses!B10 -> 95.081744
A17: VALEUR PAR ACTION (€) | E17: =E15/E16 -> 177.82864 | F17: justification de l'écart
A18: Cours (€) | E18: =Hypothèses!B9 -> 98.72 | F18: Valeur SOTP 177,8 € vs cours 98,7 € (+80 %) : dans le haut de la fourchette des analystes (145-180 €) et dans la zone des multiples de pairs (129 à 169 € au point médian selon la méthode). Lecture inverse : en gardant nos valeurs pour les concessions (3,1 + 1,7 Md€ part du Groupe) et pour Getlink (3,1 Md€), le cours ne valorise les Travaux qu'à ≈ 1,6 Md€ de capitaux propres (VE ≈ 0,3x l'EBITDA) contre 9,1 Md€ ici. Le marché applique donc sans doute des décotes : concessions APRR rendues à l'État en 2035-2036 sans indemnité, risque fiscal et tarifaire sur les autoroutes, décote de holding. Côté modèle : 69 % de la valeur des Travaux est en valeur terminale ; la valeur reste entre 157 et 207 € pour un WACC ±0,9 pt et g de 0,3 à 1,5 %. Point de vigilance : VE/EBITDA des autres concessions de 12,8x (marge 51 %, capex = APRR).
A19: Écart valeur / cours | E19: =E17/E18-1 -> 0.80134358
A22: CONTRÔLES | B22: Valeur | C22: Attendu
A23: Σ dette nette des parties vs dette nette retraitée du groupe | B23: =E8 -> 8548 | C23: =Données!$B$33+Données!$B$34 -> 8548
A24: Σ EBITDA des parties vs EBITDA groupe − holding | B24: =E4 -> 4416 | C24: =Données!$B$19-Hypothèses!B21 -> 4416
A25: Σ CA des parties vs CA groupe − holding | B25: =Travaux!B16+'Eiffarie (APRR-AREA-Aliaé)'!B17+'Autres concessions'!B16 -> 25313 | C25: =Données!$B$27 -> 25313
A27: Poids de la VE : Travaux / Eiffarie / Autres | B27: =B5/E5 -> 0.30983584 | C27: =C5/E5 -> 0.50269067 | D27: =D5/E5 -> 0.18747348

Sheet Football field
A1: Football field | valeur par action (€)
A2: Source du graphique : le tableau ci-dessous. La barre va de « Bas » à « Haut » (la partie invisible vaut « Bas », la partie colorée vaut « Écart »).
A3: Les lignes SOTP viennent de l'onglet Sensibilité, les multiples de l'onglet Multiples.
A5: Méthode | B5: Bas | C5: Haut | D5: Écart (graphique) | E5: Point central
A6: SOTP DCF (WACC ±0,3 pt ; g ±0,3 pt) | B6: =Sensibilité!D26 -> 169.42641 | C6: =Sensibilité!F24 -> 187.38615 | D6: =C6-B6 -> 17.959739 | E6: =Sensibilité!E25 -> 177.82864
A7: VE / EBITDA (Q1 à Q3 des pairs) | B7: =Multiples!F37 -> 78.277694 | C7: =Multiples!H37 -> 352.24137 | D7: =C7-B7 -> 273.96368 | E7: =Multiples!G37 -> 168.91358
A8: VE / EBIT (Q1 à Q3 des pairs) | B8: =Multiples!F38 -> 117.41749 | C8: =Multiples!H38 -> 261.43047 | D8: =C8-B8 -> 144.01297 | E8: =Multiples!G38 -> 129.39229
A9: PER (Q1 à Q3 des pairs) | B9: =Multiples!F39 -> 137.77315 | C9: =Multiples!H39 -> 185.62195 | D9: =C9-B9 -> 47.848797 | E9: =Multiples!G39 -> 145.61411
A10: Objectifs des analystes (fourchette resserrée) | B10: 145 | C10: 180 | D10: =C10-B10 -> 35 | E10: 159
A11: Cours actuel | B11: =Hypothèses!B9-1 -> 97.72 | C11: =Hypothèses!B9+1 -> 99.72 | D11: =C11-B11 -> 2 | E11: =Hypothèses!B9 -> 98.72
A13: Objectifs des analystes : fourchette resserrée 145-180 €, médiane 159 € (consensus Ideal Investisseurs à titre indicatif au 09/10/2026). Le cours est tracé comme une barre fine d'environ 1 € à titre représentatif.

Sheet Sensibilité
A1: Sensibilité de la valeur par action au WACC ET à la croissance à l’infini g
A2: Chaque case de la grille = valeur par action si on décale le WACC des trois blocs (ligne) ET la croissance à l'infini g des Travaux (colonne). Les cases du milieu = scénario central
A4: Décalage de WACC (appliqué aux 3 blocs) | B4: -0.009 | C4: -0.006 | D4: -0.003 | E4: 0 | F4: 0.003 | G4: 0.006 | H4: 0.009
A5: WACC Travaux | B5: =Travaux!$B$13+B$4 -> 0.07052 | C5: =Travaux!$B$13+C$4 -> 0.07352 | D5: =Travaux!$B$13+D$4 -> 0.07652 | E5: =Travaux!$B$13+E$4 -> 0.07952 | F5: =Travaux!$B$13+F$4 -> 0.08252 | G5: =Travaux!$B$13+G$4 -> 0.08552 | H5: =Travaux!$B$13+H$4 -> 0.08852
A6: Σ FCFF actualisés Travaux (2026-2030) | B6: =SUMPRODUCT(Travaux!$C$34:$G$34,1/(1+B5)^Travaux!$C$35:$G$35) -> 2566.973 | C6: =SUMPRODUCT(Travaux!$C$34:$G$34,1/(1+C5)^Travaux!$C$35:$G$35) -> 2545.8136 | D6: =SUMPRODUCT(Travaux!$C$34:$G$34,1/(1+D5)^Travaux!$C$35:$G$35) -> 2524.9263 | E6: =SUMPRODUCT(Travaux!$C$34:$G$34,1/(1+E5)^Travaux!$C$35:$G$35) -> 2504.3065 | F6: =SUMPRODUCT(Travaux!$C$34:$G$34,1/(1+F5)^Travaux!$C$35:$G$35) -> 2483.95 | G6: =SUMPRODUCT(Travaux!$C$34:$G$34,1/(1+G5)^Travaux!$C$35:$G$35) -> 2463.8523 | H6: =SUMPRODUCT(Travaux!$C$34:$G$34,1/(1+H5)^Travaux!$C$35:$G$35) -> 2444.0093
A7: WACC Eiffarie | B7: ='Eiffarie (APRR-AREA-Aliaé)'!$B$13+B$4 -> 0.046888681 | C7: ='Eiffarie (APRR-AREA-Aliaé)'!$B$13+C$4 -> 0.049888681 | D7: ='Eiffarie (APRR-AREA-Aliaé)'!$B$13+D$4 -> 0.052888681 | E7: ='Eiffarie (APRR-AREA-Aliaé)'!$B$13+E$4 -> 0.055888681 | F7: ='Eiffarie (APRR-AREA-Aliaé)'!$B$13+F$4 -> 0.058888681 | G7: ='Eiffarie (APRR-AREA-Aliaé)'!$B$13+G$4 -> 0.061888681 | H7: ='Eiffarie (APRR-AREA-Aliaé)'!$B$13+H$4 -> 0.064888681
A8: VE Eiffarie | B8: =SUMPRODUCT('Eiffarie (APRR-AREA-Aliaé)'!$C$35:$L$35,1/(1+B7)^'Eiffarie (APRR-AREA-Aliaé)'!$C$36:$L$36) -> 13625.247 | C8: =SUMPRODUCT('Eiffarie (APRR-AREA-Aliaé)'!$C$35:$L$35,1/(1+C7)^'Eiffarie (APRR-AREA-Aliaé)'!$C$36:$L$36) -> 13419.624 | D8: =SUMPRODUCT('Eiffarie (APRR-AREA-Aliaé)'!$C$35:$L$35,1/(1+D7)^'Eiffarie (APRR-AREA-Aliaé)'!$C$36:$L$36) -> 13218.565 | E8: =SUMPRODUCT('Eiffarie (APRR-AREA-Aliaé)'!$C$35:$L$35,1/(1+E7)^'Eiffarie (APRR-AREA-Aliaé)'!$C$36:$L$36) -> 13021.946 | F8: =SUMPRODUCT('Eiffarie (APRR-AREA-Aliaé)'!$C$35:$L$35,1/(1+F7)^'Eiffarie (APRR-AREA-Aliaé)'!$C$36:$L$36) -> 12829.645 | G8: =SUMPRODUCT('Eiffarie (APRR-AREA-Aliaé)'!$C$35:$L$35,1/(1+G7)^'Eiffarie (APRR-AREA-Aliaé)'!$C$36:$L$36) -> 12641.548 | H8: =SUMPRODUCT('Eiffarie (APRR-AREA-Aliaé)'!$C$35:$L$35,1/(1+H7)^'Eiffarie (APRR-AREA-Aliaé)'!$C$36:$L$36) -> 12457.542
A9: WACC autres concessions | B9: ='Autres concessions'!$B$13+B$4 -> 0.051097421 | C9: ='Autres concessions'!$B$13+C$4 -> 0.054097421 | D9: ='Autres concessions'!$B$13+D$4 -> 0.057097421 | E9: ='Autres concessions'!$B$13+E$4 -> 0.060097421 | F9: ='Autres concessions'!$B$13+F$4 -> 0.063097421 | G9: ='Autres concessions'!$B$13+G$4 -> 0.066097421 | H9: ='Autres concessions'!$B$13+H$4 -> 0.069097421
A10: Σ FCFF actualisés autres (2026-2040) | B10: =SUMPRODUCT('Autres concessions'!$C$34:$Q$34,1/(1+B9)^'Autres concessions'!$C$35:$Q$35) -> 3144.0701 | C10: =SUMPRODUCT('Autres concessions'!$C$34:$Q$34,1/(1+C9)^'Autres concessions'!$C$35:$Q$35) -> 3077.5292 | D10: =SUMPRODUCT('Autres concessions'!$C$34:$Q$34,1/(1+D9)^'Autres concessions'!$C$35:$Q$35) -> 3013.0307 | E10: =SUMPRODUCT('Autres concessions'!$C$34:$Q$34,1/(1+E9)^'Autres concessions'!$C$35:$Q$35) -> 2950.4991 | F10: =SUMPRODUCT('Autres concessions'!$C$34:$Q$34,1/(1+F9)^'Autres concessions'!$C$35:$Q$35) -> 2889.8625 | G10: =SUMPRODUCT('Autres concessions'!$C$34:$Q$34,1/(1+G9)^'Autres concessions'!$C$35:$Q$35) -> 2831.0516 | H10: =SUMPRODUCT('Autres concessions'!$C$34:$Q$34,1/(1+H9)^'Autres concessions'!$C$35:$Q$35) -> 2774.0002
A11: Annuité actualisée après 2040 (autres) | B11: =IF('Autres concessions'!$B$44>0,'Autres concessions'!$Q$34*(1+'Autres concessions'!$B$42)/(B9-'Autres concessions'!$B$42)*(1-((1+'Autres concessions'!$B$42)/(1+B9))^'Autres concessions'!$B$44)/(1+B9)^'Autres concessions'!$Q$35,0) -> 2339.0558 | C11: =IF('Autres concessions'!$B$44>0,'Autres concessions'!$Q$34*(1+'Autres concessions'!$B$42)/(C9-'Autres concessions'!$B$42)*(1-((1+'Autres concessions'!$B$42)/(1+C9))^'Autres concessions'!$B$44)/(1+C9)^'Autres concessions'!$Q$35,0) -> 2183.7233 | D11: =IF('Autres concessions'!$B$44>0,'Autres concessions'!$Q$34*(1+'Autres concessions'!$B$42)/(D9-'Autres concessions'!$B$42)*(1-((1+'Autres concessions'!$B$42)/(1+D9))^'Autres concessions'!$B$44)/(1+D9)^'Autres concessions'!$Q$35,0) -> 2039.6324 | E11: =IF('Autres concessions'!$B$44>0,'Autres concessions'!$Q$34*(1+'Autres concessions'!$B$42)/(E9-'Autres concessions'!$B$42)*(1-((1+'Autres concessions'!$B$42)/(1+E9))^'Autres concessions'!$B$44)/(1+E9)^'Autres concessions'!$Q$35,0) -> 1905.9059 | F11: =IF('Autres concessions'!$B$44>0,'Autres concessions'!$Q$34*(1+'Autres concessions'!$B$42)/(F9-'Autres concessions'!$B$42)*(1-((1+'Autres concessions'!$B$42)/(1+F9))^'Autres concessions'!$B$44)/(1+F9)^'Autres concessions'!$Q$35,0) -> 1781.7398 | G11: =IF('Autres concessions'!$B$44>0,'Autres concessions'!$Q$34*(1+'Autres concessions'!$B$42)/(G9-'Autres concessions'!$B$42)*(1-((1+'Autres concessions'!$B$42)/(1+G9))^'Autres concessions'!$B$44)/(1+G9)^'Autres concessions'!$Q$35,0) -> 1666.3965 | H11: =IF('Autres concessions'!$B$44>0,'Autres concessions'!$Q$34*(1+'Autres concessions'!$B$42)/(H9-'Autres concessions'!$B$42)*(1-((1+'Autres concessions'!$B$42)/(1+H9))^'Autres concessions'!$B$44)/(1+H9)^'Autres concessions'!$Q$35,0) -> 1559.1995
A12: VE autres concessions | B12: =B10+B11 -> 5483.1259 | C12: =C10+C11 -> 5261.2525 | D12: =D10+D11 -> 5052.663 | E12: =E10+E11 -> 4856.405 | F12: =F10+F11 -> 4671.6023 | G12: =G10+G11 -> 4497.4481 | H12: =H10+H11 -> 4333.1996
A13: Eiffarie, part du Groupe | B13: =MAX(B8-SOTP!$C$8,0)*SOTP!$C$10 -> 3409.4795 | C13: =MAX(C8-SOTP!$C$8,0)*SOTP!$C$10 -> 3301.5278 | D13: =MAX(D8-SOTP!$C$8,0)*SOTP!$C$10 -> 3195.9718 | E13: =MAX(E8-SOTP!$C$8,0)*SOTP!$C$10 -> 3092.7464 | F13: =MAX(F8-SOTP!$C$8,0)*SOTP!$C$10 -> 2991.7888 | G13: =MAX(G8-SOTP!$C$8,0)*SOTP!$C$10 -> 2893.0379 | H13: =MAX(H8-SOTP!$C$8,0)*SOTP!$C$10 -> 2796.4346
A14: Autres concessions, part du Groupe | B14: =MAX(B12-SOTP!$D$8,0)*SOTP!$D$10 -> 2284.3133 | C14: =MAX(C12-SOTP!$D$8,0)*SOTP!$D$10 -> 2084.6273 | D14: =MAX(D12-SOTP!$D$8,0)*SOTP!$D$10 -> 1896.8967 | E14: =MAX(E12-SOTP!$D$8,0)*SOTP!$D$10 -> 1720.2645 | F14: =MAX(F12-SOTP!$D$8,0)*SOTP!$D$10 -> 1553.942 | G14: =MAX(G12-SOTP!$D$8,0)*SOTP!$D$10 -> 1397.2033 | H14: =MAX(H12-SOTP!$D$8,0)*SOTP!$D$10 -> 1249.3797
A19: GRILLE : valeur par action (€) – lignes = décalage du WACC ; colonnes = g des Travaux
A20: Décalage de g | C20: -0.006 | D20: -0.003 | E20: 0 | F20: 0.003 | G20: 0.006
A21: Décalage WACC ↓ / g Travaux → | B21: WACC Travaux | C21: =Travaux!$B$42+C20 -> 0.003 | D21: =Travaux!$B$42+D20 -> 0.006 | E21: =Travaux!$B$42+E20 -> 0.009 | F21: =Travaux!$B$42+F20 -> 0.012 | G21: =Travaux!$B$42+G20 -> 0.015
A22: =B4 -> -0.009 | B22: =B5 -> 0.07052 | C22: =((B$6+Travaux!$G$30*(1+C$21)/(B$5-C$21)/(1+B$5)^Travaux!$G$35)-SOTP!$B$8-SOTP!$B$11+B$13+B$14+SOTP!$E$13+Hypothèses!$B$21*(B$6+Travaux!$G$30*(1+C$21)/(B$5-C$21)/(1+B$5)^Travaux!$G$35)/SOTP!$B$4)/Hypothèses!$B$10 -> 192.47979 | D22: =((B$6+Travaux!$G$30*(1+D$21)/(B$5-D$21)/(1+B$5)^Travaux!$G$35)-SOTP!$B$8-SOTP!$B$11+B$13+B$14+SOTP!$E$13+Hypothèses!$B$21*(B$6+Travaux!$G$30*(1+D$21)/(B$5-D$21)/(1+B$5)^Travaux!$G$35)/SOTP!$B$4)/Hypothèses!$B$10 -> 195.56078 | E22: =((B$6+Travaux!$G$30*(1+E$21)/(B$5-E$21)/(1+B$5)^Travaux!$G$35)-SOTP!$B$8-SOTP!$B$11+B$13+B$14+SOTP!$E$13+Hypothèses!$B$21*(B$6+Travaux!$G$30*(1+E$21)/(B$5-E$21)/(1+B$5)^Travaux!$G$35)/SOTP!$B$4)/Hypothèses!$B$10 -> 198.94227 | F22: =((B$6+Travaux!$G$30*(1+F$21)/(B$5-F$21)/(1+B$5)^Travaux!$G$35)-SOTP!$B$8-SOTP!$B$11+B$13+B$14+SOTP!$E$13+Hypothèses!$B$21*(B$6+Travaux!$G$30*(1+F$21)/(B$5-F$21)/(1+B$5)^Travaux!$G$35)/SOTP!$B$4)/Hypothèses!$B$10 -> 202.67045 | G22: =((B$6+Travaux!$G$30*(1+G$21)/(B$5-G$21)/(1+B$5)^Travaux!$G$35)-SOTP!$B$8-SOTP!$B$11+B$13+B$14+SOTP!$E$13+Hypothèses!$B$21*(B$6+Travaux!$G$30*(1+G$21)/(B$5-G$21)/(1+B$5)^Travaux!$G$35)/SOTP!$B$4)/Hypothèses!$B$10 -> 206.80154
A23: =C4 -> -0.006 | B23: =C5 -> 0.07352 | C23: =((C$6+Travaux!$G$30*(1+C$21)/(C$5-C$21)/(1+C$5)^Travaux!$G$35)-SOTP!$B$8-SOTP!$B$11+C$13+C$14+SOTP!$E$13+Hypothèses!$B$21*(C$6+Travaux!$G$30*(1+C$21)/(C$5-C$21)/(1+C$5)^Travaux!$G$35)/SOTP!$B$4)/Hypothèses!$B$10 -> 185.55754 | D23: =((C$6+Travaux!$G$30*(1+D$21)/(C$5-D$21)/(1+C$5)^Travaux!$G$35)-SOTP!$B$8-SOTP!$B$11+C$13+C$14+SOTP!$E$13+Hypothèses!$B$21*(C$6+Travaux!$G$30*(1+D$21)/(C$5-D$21)/(1+C$5)^Travaux!$G$35)/SOTP!$B$4)/Hypothèses!$B$10 -> 188.34502 | E23: =((C$6+Travaux!$G$30*(1+E$21)/(C$5-E$21)/(1+C$5)^Travaux!$G$35)-SOTP!$B$8-SOTP!$B$11+C$13+C$14+SOTP!$E$13+Hypothèses!$B$21*(C$6+Travaux!$G$30*(1+E$21)/(C$5-E$21)/(1+C$5)^Travaux!$G$35)/SOTP!$B$4)/Hypothèses!$B$10 -> 191.39172 | F23: =((C$6+Travaux!$G$30*(1+F$21)/(C$5-F$21)/(1+C$5)^Travaux!$G$35)-SOTP!$B$8-SOTP!$B$11+C$13+C$14+SOTP!$E$13+Hypothèses!$B$21*(C$6+Travaux!$G$30*(1+F$21)/(C$5-F$21)/(1+C$5)^Travaux!$G$35)/SOTP!$B$4)/Hypothèses!$B$10 -> 194.73556 | G23: =((C$6+Travaux!$G$30*(1+G$21)/(C$5-G$21)/(1+C$5)^Travaux!$G$35)-SOTP!$B$8-SOTP!$B$11+C$13+C$14+SOTP!$E$13+Hypothèses!$B$21*(C$6+Travaux!$G$30*(1+G$21)/(C$5-G$21)/(1+C$5)^Travaux!$G$35)/SOTP!$B$4)/Hypothèses!$B$10 -> 198.42224
A24: =D4 -> -0.003 | B24: =D5 -> 0.07652 | C24: =((D$6+Travaux!$G$30*(1+C$21)/(D$5-C$21)/(1+D$5)^Travaux!$G$35)-SOTP!$B$8-SOTP!$B$11+D$13+D$14+SOTP!$E$13+Hypothèses!$B$21*(D$6+Travaux!$G$30*(1+C$21)/(D$5-C$21)/(1+D$5)^Travaux!$G$35)/SOTP!$B$4)/Hypothèses!$B$10 -> 179.08516 | D24: =((D$6+Travaux!$G$30*(1+D$21)/(D$5-D$21)/(1+D$5)^Travaux!$G$35)-SOTP!$B$8-SOTP!$B$11+D$13+D$14+SOTP!$E$13+Hypothèses!$B$21*(D$6+Travaux!$G$30*(1+D$21)/(D$5-D$21)/(1+D$5)^Travaux!$G$35)/SOTP!$B$4)/Hypothèses!$B$10 -> 181.61673 | E24: =((D$6+Travaux!$G$30*(1+E$21)/(D$5-E$21)/(1+D$5)^Travaux!$G$35)-SOTP!$B$8-SOTP!$B$11+D$13+D$14+SOTP!$E$13+Hypothèses!$B$21*(D$6+Travaux!$G$30*(1+E$21)/(D$5-E$21)/(1+D$5)^Travaux!$G$35)/SOTP!$B$4)/Hypothèses!$B$10 -> 184.37327 | F24: =((D$6+Travaux!$G$30*(1+F$21)/(D$5-F$21)/(1+D$5)^Travaux!$G$35)-SOTP!$B$8-SOTP!$B$11+D$13+D$14+SOTP!$E$13+Hypothèses!$B$21*(D$6+Travaux!$G$30*(1+F$21)/(D$5-F$21)/(1+D$5)^Travaux!$G$35)/SOTP!$B$4)/Hypothèses!$B$10 -> 187.38615 | G24: =((D$6+Travaux!$G$30*(1+G$21)/(D$5-G$21)/(1+D$5)^Travaux!$G$35)-SOTP!$B$8-SOTP!$B$11+D$13+D$14+SOTP!$E$13+Hypothèses!$B$21*(D$6+Travaux!$G$30*(1+G$21)/(D$5-G$21)/(1+D$5)^Travaux!$G$35)/SOTP!$B$4)/Hypothèses!$B$10 -> 190.69288
A25: =E4 -> 0 | B25: =E5 -> 0.07952 | C25: =((E$6+Travaux!$G$30*(1+C$21)/(E$5-C$21)/(1+E$5)^Travaux!$G$35)-SOTP!$B$8-SOTP!$B$11+E$13+E$14+SOTP!$E$13+Hypothèses!$B$21*(E$6+Travaux!$G$30*(1+C$21)/(E$5-C$21)/(1+E$5)^Travaux!$G$35)/SOTP!$B$4)/Hypothèses!$B$10 -> 173.01784 | D25: =((E$6+Travaux!$G$30*(1+D$21)/(E$5-D$21)/(1+E$5)^Travaux!$G$35)-SOTP!$B$8-SOTP!$B$11+E$13+E$14+SOTP!$E$13+Hypothèses!$B$21*(E$6+Travaux!$G$30*(1+D$21)/(E$5-D$21)/(1+E$5)^Travaux!$G$35)/SOTP!$B$4)/Hypothèses!$B$10 -> 175.32509 | E25: =((E$6+Travaux!$G$30*(1+E$21)/(E$5-E$21)/(1+E$5)^Travaux!$G$35)-SOTP!$B$8-SOTP!$B$11+E$13+E$14+SOTP!$E$13+Hypothèses!$B$21*(E$6+Travaux!$G$30*(1+E$21)/(E$5-E$21)/(1+E$5)^Travaux!$G$35)/SOTP!$B$4)/Hypothèses!$B$10 -> 177.82864 | F25: =((E$6+Travaux!$G$30*(1+F$21)/(E$5-F$21)/(1+E$5)^Travaux!$G$35)-SOTP!$B$8-SOTP!$B$11+E$13+E$14+SOTP!$E$13+Hypothèses!$B$21*(E$6+Travaux!$G$30*(1+F$21)/(E$5-F$21)/(1+E$5)^Travaux!$G$35)/SOTP!$B$4)/Hypothèses!$B$10 -> 180.55466 | G25: =((E$6+Travaux!$G$30*(1+G$21)/(E$5-G$21)/(1+E$5)^Travaux!$G$35)-SOTP!$B$8-SOTP!$B$11+E$13+E$14+SOTP!$E$13+Hypothèses!$B$21*(E$6+Travaux!$G$30*(1+G$21)/(E$5-G$21)/(1+E$5)^Travaux!$G$35)/SOTP!$B$4)/Hypothèses!$B$10 -> 183.53419
A26: =F4 -> 0.003 | B26: =F5 -> 0.08252 | C26: =((F$6+Travaux!$G$30*(1+C$21)/(F$5-C$21)/(1+F$5)^Travaux!$G$35)-SOTP!$B$8-SOTP!$B$11+F$13+F$14+SOTP!$E$13+Hypothèses!$B$21*(F$6+Travaux!$G$30*(1+C$21)/(F$5-C$21)/(1+F$5)^Travaux!$G$35)/SOTP!$B$4)/Hypothèses!$B$10 -> 167.31681 | D26: =((F$6+Travaux!$G$30*(1+D$21)/(F$5-D$21)/(1+F$5)^Travaux!$G$35)-SOTP!$B$8-SOTP!$B$11+F$13+F$14+SOTP!$E$13+Hypothèses!$B$21*(F$6+Travaux!$G$30*(1+D$21)/(F$5-D$21)/(1+F$5)^Travaux!$G$35)/SOTP!$B$4)/Hypothèses!$B$10 -> 169.42641 | E26: =((F$6+Travaux!$G$30*(1+E$21)/(F$5-E$21)/(1+F$5)^Travaux!$G$35)-SOTP!$B$8-SOTP!$B$11+F$13+F$14+SOTP!$E$13+Hypothèses!$B$21*(F$6+Travaux!$G$30*(1+E$21)/(F$5-E$21)/(1+F$5)^Travaux!$G$35)/SOTP!$B$4)/Hypothèses!$B$10 -> 171.70819 | F26: =((F$6+Travaux!$G$30*(1+F$21)/(F$5-F$21)/(1+F$5)^Travaux!$G$35)-SOTP!$B$8-SOTP!$B$11+F$13+F$14+SOTP!$E$13+Hypothèses!$B$21*(F$6+Travaux!$G$30*(1+F$21)/(F$5-F$21)/(1+F$5)^Travaux!$G$35)/SOTP!$B$4)/Hypothèses!$B$10 -> 174.1841 | G26: =((F$6+Travaux!$G$30*(1+G$21)/(F$5-G$21)/(1+F$5)^Travaux!$G$35)-SOTP!$B$8-SOTP!$B$11+F$13+F$14+SOTP!$E$13+Hypothèses!$B$21*(F$6+Travaux!$G$30*(1+G$21)/(F$5-G$21)/(1+F$5)^Travaux!$G$35)/SOTP!$B$4)/Hypothèses!$B$10 -> 176.88004
A27: =G4 -> 0.006 | B27: =G5 -> 0.08552 | C27: =((G$6+Travaux!$G$30*(1+C$21)/(G$5-C$21)/(1+G$5)^Travaux!$G$35)-SOTP!$B$8-SOTP!$B$11+G$13+G$14+SOTP!$E$13+Hypothèses!$B$21*(G$6+Travaux!$G$30*(1+C$21)/(G$5-C$21)/(1+G$5)^Travaux!$G$35)/SOTP!$B$4)/Hypothèses!$B$10 -> 161.94829 | D27: =((G$6+Travaux!$G$30*(1+D$21)/(G$5-D$21)/(1+G$5)^Travaux!$G$35)-SOTP!$B$8-SOTP!$B$11+G$13+G$14+SOTP!$E$13+Hypothèses!$B$21*(G$6+Travaux!$G$30*(1+D$21)/(G$5-D$21)/(1+G$5)^Travaux!$G$35)/SOTP!$B$4)/Hypothèses!$B$10 -> 163.88297 | E27: =((G$6+Travaux!$G$30*(1+E$21)/(G$5-E$21)/(1+G$5)^Travaux!$G$35)-SOTP!$B$8-SOTP!$B$11+G$13+G$14+SOTP!$E$13+Hypothèses!$B$21*(G$6+Travaux!$G$30*(1+E$21)/(G$5-E$21)/(1+G$5)^Travaux!$G$35)/SOTP!$B$4)/Hypothèses!$B$10 -> 165.96936 | F27: =((G$6+Travaux!$G$30*(1+F$21)/(G$5-F$21)/(1+G$5)^Travaux!$G$35)-SOTP!$B$8-SOTP!$B$11+G$13+G$14+SOTP!$E$13+Hypothèses!$B$21*(G$6+Travaux!$G$30*(1+F$21)/(G$5-F$21)/(1+G$5)^Travaux!$G$35)/SOTP!$B$4)/Hypothèses!$B$10 -> 168.22602 | G27: =((G$6+Travaux!$G$30*(1+G$21)/(G$5-G$21)/(1+G$5)^Travaux!$G$35)-SOTP!$B$8-SOTP!$B$11+G$13+G$14+SOTP!$E$13+Hypothèses!$B$21*(G$6+Travaux!$G$30*(1+G$21)/(G$5-G$21)/(1+G$5)^Travaux!$G$35)/SOTP!$B$4)/Hypothèses!$B$10 -> 170.67467
A28: =H4 -> 0.009 | B28: =H5 -> 0.08852 | C28: =((H$6+Travaux!$G$30*(1+C$21)/(H$5-C$21)/(1+H$5)^Travaux!$G$35)-SOTP!$B$8-SOTP!$B$11+H$13+H$14+SOTP!$E$13+Hypothèses!$B$21*(H$6+Travaux!$G$30*(1+C$21)/(H$5-C$21)/(1+H$5)^Travaux!$G$35)/SOTP!$B$4)/Hypothèses!$B$10 -> 156.88273 | D28: =((H$6+Travaux!$G$30*(1+D$21)/(H$5-D$21)/(1+H$5)^Travaux!$G$35)-SOTP!$B$8-SOTP!$B$11+H$13+H$14+SOTP!$E$13+Hypothèses!$B$21*(H$6+Travaux!$G$30*(1+D$21)/(H$5-D$21)/(1+H$5)^Travaux!$G$35)/SOTP!$B$4)/Hypothèses!$B$10 -> 158.66193 | E28: =((H$6+Travaux!$G$30*(1+E$21)/(H$5-E$21)/(1+H$5)^Travaux!$G$35)-SOTP!$B$8-SOTP!$B$11+H$13+H$14+SOTP!$E$13+Hypothèses!$B$21*(H$6+Travaux!$G$30*(1+E$21)/(H$5-E$21)/(1+H$5)^Travaux!$G$35)/SOTP!$B$4)/Hypothèses!$B$10 -> 160.57537 | F28: =((H$6+Travaux!$G$30*(1+F$21)/(H$5-F$21)/(1+H$5)^Travaux!$G$35)-SOTP!$B$8-SOTP!$B$11+H$13+H$14+SOTP!$E$13+Hypothèses!$B$21*(H$6+Travaux!$G$30*(1+F$21)/(H$5-F$21)/(1+H$5)^Travaux!$G$35)/SOTP!$B$4)/Hypothèses!$B$10 -> 162.63885 | G28: =((H$6+Travaux!$G$30*(1+G$21)/(H$5-G$21)/(1+H$5)^Travaux!$G$35)-SOTP!$B$8-SOTP!$B$11+H$13+H$14+SOTP!$E$13+Hypothèses!$B$21*(H$6+Travaux!$G$30*(1+G$21)/(H$5-G$21)/(1+H$5)^Travaux!$G$35)/SOTP!$B$4)/Hypothèses!$B$10 -> 164.87073
A30: Contrôle avec valeur du SOTP!E17 | B30: =E25-SOTP!E17 -> 0
A32: g n’agit que sur la valeur terminale des Travaux : les concessions ont une durée finie, elles n’ont pas de g à l’infini.
A33: Fourchette retenue pour le football field : de (WACC +0,3 pt ; g −0,3 pt) à (WACC −0,3 pt ; g +0,3 pt).

Sheet Travaux
A1: Travaux (Construction, Infrastructures, Énergie Systèmes)
A3: COÛT DU CAPITAL | B3: Valeur
A4: Taux sans risque | B4: =Hypothèses!B5 -> 0.04
A5: Bêta désendetté (βu) | B5: 0.8 | C5: Damodaran Europe, Engineering/Construction, janv. 2026
A6: D/E cible | B6: 0 | C6: Trésorerie nette de 1 528 M€ : dette nette nulle
A7: Taux d'impôt | B7: =Hypothèses!B7 -> 0.268
A8: Bêta réendetté | B8: =B5*(1+(1-B7)*B6) -> 0.8 | C8: Formule d'Hamada : βL = βu × (1 + (1 - t) × D/E)
A9: Prime de risque du marché (ERP) | B9: =Hypothèses!B6 -> 0.0494
A10: Coût des capitaux propres (Ke) | B10: =B4+B8*B9 -> 0.07952 | C10: Formule du MEDAF
A11: Coût de la dette avant impôt (Kd) | B11: =Hypothèses!B24+Hypothèses!B5 -> 0.05 | C11: Rf + spread (Hypothèse sans impact car D/E = 0)
A12: E/V | B12: =1/(1+B6) -> 1
A13: WACC | B13: =B12*B10+(1-B12)*B11*(1-B7) -> 0.07952
A15: HYPOTHESES | B15: Valeur
A16: CA 2025 | B16: =Données!$B$25 -> 21335 | C16: DEU 2025 note 5.1 : CA Travaux publié
A17: Marge d'EBITDA | B17: 0.065 | C17: Hypothèse prudente (6,5 %), inférieure à la marge réelle 2024 (7,1 %) et 2025 (8,2 %) : prudence liée à l'économie du secteur (construction cyclique, marges fines)
A18: Dotations (% du CA) | B18: =(Données!$B$13+Données!$B$14+Données!$B$15)/B16 -> 0.036559644 | C18: Réel 2025 : (68 + 455 + 257) / CA Travaux, DEU 2025 note 4.1
A19: Capex + loyers (% du CA) | B19: 0.038 | C19: Hypothèse : au-dessus des dotations (3,7%) car l'activité croît mais tout de même en dessous de la borne haute (5,1%)
A20: BFR encaissé (% de la hausse du CA) | B20: 0.13 | C20: Hypothèse : Travaux a un BFR négatif (clients payent avant que Eiffage ne paye les fournisseurs). Prudente, 2025 au niveau Groupe :13,7%
A21: EBITDA 2025 (réel) | B21: =Données!$B$6+Données!$B$7+Données!$B$8+Données!$B$13+Données!$B$14+Données!$B$15 -> 1753 | C21: Réel 2025 : ROC + dotations des trois branches (DEU 2025, note 4.1)
A23: M€ | B23: 2025 | C23: 2026 | D23: 2027 | E23: 2028 | F23: 2029 | G23: 2030
A24: Chiffre d'affaires | B24: =B16 -> 21335 | C24: =B24*(1+C25) -> 22393.216 | D24: =C24*(1+D25) -> 23503.92 | E24: =D24*(1+E25) -> 24669.714 | F24: =E24*(1+F25) -> 25893.332 | G24: =F24*(1+G25) -> 27177.641
A25: Croissance (Damodaran, Engineering/Construction Europe de l'Ouest, 5 ans : 4,96 %) | C25: 0.0496 | D25: 0.0496 | E25: 0.0496 | F25: 0.0496 | G25: 0.0496
A26: EBITDA | B26: =B21 -> 1753 | C26: =C24*$B$17 -> 1455.559 | D26: =D24*$B$17 -> 1527.7548 | E26: =E24*$B$17 -> 1603.5314 | F26: =F24*$B$17 -> 1683.0666 | G26: =G24*$B$17 -> 1766.5467
A27: – Dotations | C27: =C24*$B$18 -> 818.688 | D27: =D24*$B$18 -> 859.29492 | E27: =E24*$B$18 -> 901.91595 | F27: =F24*$B$18 -> 946.65098 | G27: =G24*$B$18 -> 993.60487
A28: EBIT | C28: =C26-C27 -> 636.87104 | D28: =D26-D27 -> 668.45984 | E28: =E26-E27 -> 701.61545 | F28: =F26-F27 -> 736.41558 | G28: =G26-G27 -> 772.94179
A29: – Impôt | C29: =MAX(C28,0)*$B$7 -> 170.68144 | D29: =MAX(D28,0)*$B$7 -> 179.14724 | E29: =MAX(E28,0)*$B$7 -> 188.03294 | F29: =MAX(F28,0)*$B$7 -> 197.35937 | G29: =MAX(G28,0)*$B$7 -> 207.1484
A30: NOPAT | C30: =C28-C29 -> 466.1896 | D30: =D28-D29 -> 489.31261 | E30: =E28-E29 -> 513.58251 | F30: =F28-F29 -> 539.0562 | G30: =G28-G29 -> 565.79339
A31: + Dotations | C31: =C27 -> 818.688 | D31: =D27 -> 859.29492 | E31: =E27 -> 901.91595 | F31: =F27 -> 946.65098 | G31: =G27 -> 993.60487
A32: – Capex et loyers | C32: =C24*$B$19 -> 850.94221 | D32: =D24*$B$19 -> 893.14894 | E32: =E24*$B$19 -> 937.44913 | F32: =F24*$B$19 -> 983.94661 | G32: =G24*$B$19 -> 1032.7504
A33: + BFR (encaissement) | C33: =(C24-B24)*$B$20 -> 137.56808 | D33: =(D24-C24)*$B$20 -> 144.39146 | E33: =(E24-D24)*$B$20 -> 151.55327 | F33: =(F24-E24)*$B$20 -> 159.07032 | G33: =(G24-F24)*$B$20 -> 166.9602
A34: FCFF | C34: =C30+C31-C32+C33 -> 571.50347 | D34: =D30+D31-D32+D33 -> 599.85005 | E34: =E30+E31-E32+E33 -> 629.60261 | F34: =F30+F31-F32+F33 -> 660.8309 | G34: =G30+G31-G32+G33 -> 693.60811
A35: Période (années) | C35: 1 | D35: 2 | E35: 3 | F35: 4 | G35: 5
A36: Facteur d'actualisation | C36: =1/(1+$B$13)^C35 -> 0.92633763 | D36: =1/(1+$B$13)^D35 -> 0.85810141 | E36: =1/(1+$B$13)^E35 -> 0.79489163 | F36: =1/(1+$B$13)^F35 -> 0.73633803 | G36: =1/(1+$B$13)^G35 -> 0.68209762
A37: FCFF actualisé | C37: =C34*C36 -> 529.40517 | D37: =D34*D36 -> 514.73217 | E37: =E34*E36 -> 500.46584 | F37: =F34*F36 -> 486.59492 | G37: =G34*G36 -> 473.10844
A40: VALORISATION | B40: Valeur
A41: Somme des FCFF actualisés | B41: =SUM(C37:G37) -> 2504.3065
A42: Croissance à l'infini (g) | B42: 0.009 | C42: Hypothèse prudente, inférieure à l'inflation (scénarios testés : 0,9 % / 1,2 % / 1,5 %, onglet Sensibilité)
A43: FCFF terminal (= NOPAT final : capex = dotations) | B43: =G30 -> 565.79339
A44: Valeur terminale (Gordon-Shapiro) | B44: =B43*(1+B42)/(B13-B42) -> 8095.3706
A45: Valeur terminale actualisée | B45: =B44*G36 -> 5521.833
...

Sheet Eiffarie (APRR-AREA-Aliaé)
A1: FINANCIÈRE EIFFARIE = APRR + AREA + ALIAÉ | DCF jusqu'à l'échéance (2035-2036)
A3: COÛT DU CAPITAL | B3: Valeur
A4: Taux sans risque | B4: =Hypothèses!B5 -> 0.04
A5: Bêta désendetté (βu) | B5: 0.48 | C5: Damodaran : entre Utility (0,41) et Transportation (0,54)
A6: D/E cible | B6: 1.2105018 | C6: Hypothèse de structure financière = dette nette / valeur des capitaux propres du DCF (voir B14)
A7: Taux d'impôt | B7: =Hypothèses!B8 -> 0.291
A8: Bêta réendetté | B8: =B5*(1+(1-B7)*B6) -> 0.89195796
A9: Prime de risque | B9: =Hypothèses!B6 -> 0.0494
A10: Coût des capitaux propres | B10: =B4+B8*B9 -> 0.084062723
A11: Coût de la dette avant impôt (Kd) | B11: =Hypothèses!B5+Hypothèses!B25 -> 0.046 | C11: Rf + spread (Hypothèses!B25)
A12: E/V | B12: =1/(1+B6) -> 0.45238598
A13: WACC | B13: =B12*B10+(1-B12)*B11*(1-B7) -> 0.055888681
A14: Contrôle : D/E implicite du DCF (dette nette / capitaux propres) | B14: =Hypothèses!B15/(B43-Hypothèses!B15) -> 1.2105018 | C14: Écart : | D14: =B14-B6 -> 4.2033044e-12
A16: HYPOTHESES | B16: Valeur
A17: CA 2025 | B17: =Données!$B$28+Données!$B$29 -> 3239.7 | C17: DEU 2025 note 5.1 : APRR-AREA 3 183 + Aliaé 56,7 (p.225) = périmètre Financière Eiffarie
A18: Marge d'EBITDA | B18: =Données!$B$71 -> 0.7035656 | C18: Marge réelle de l'EBITDA du groupe APRR consolidé (APRR + AREA + Aliaé = Eiffarie), comptes APRR 2025 : 2 283 / 3 244,9
A19: Dotations (% du CA) | B19: =Données!$B$72 -> 0.18906592 | C19: Réel APRR 2025 : dotations 613,5 / CA
A20: Capex + loyers (% du CA) | B20: =Données!$B$73 -> 0.082313785 | C20: Réel APRR 2025 : (investissements 261,7 + loyers = 5,4) / CA 3 244,9
A21: BFR encaissé (% de la hausse du CA) | B21: 0 | C21: Hypothèse : péages encaissés immédiatement, BFR négligeable
A22: EBITDA 2025 (réel) | B22: =Données!$B$58 -> 2283 | C22: Réel : EBITDA APRR consolidé 2025 (comptes APRR)
A24: M€ | B24: 2025 | C24: 2026 | D24: 2027 | E24: 2028 | F24: 2029 | G24: 2030 | H24: 2031 | I24: 2032 | J24: 2033 | K24: 2034 | L24: 2035
A25: Chiffre d'affaires | B25: =B17 -> 3239.7 | C25: =B25*(1+C26) -> 3320.6925 | D25: =C25*(1+D26) -> 3403.7098 | E25: =D25*(1+E26) -> 3488.8026 | F25: =E25*(1+F26) -> 3576.0226 | G25: =F25*(1+G26) -> 3665.4232 | H25: =G25*(1+H26) -> 3757.0588 | I25: =H25*(1+I26) -> 3850.9852 | J25: =I25*(1+J26) -> 3947.2599 | ... L25: =K25*(1+L26) -> 4147.0899
A26: Croissance | C26: 0.025 | D26: 0.025 | E26: 0.025 | F26: 0.025 | G26: 0.025 | H26: 0.025 | I26: 0.025 | J26: 0.025 | K26: 0.025 | L26: 0.025
A27: EBITDA | B27: =B22 -> 2283 | C27: =C25*$B$18 -> 2336.325 | D27: =D25*$B$18 -> 2394.7331 | E27: =E25*$B$18 -> 2454.6014 | F27: =F25*$B$18 -> 2515.9665 | G27: =G25*$B$18 -> 2578.8656 | H27: =H25*$B$18 -> 2643.3373 | I27: =I25*$B$18 -> 2709.4207 | J27: =J25*$B$18 -> 2777.1562 | ... L27: =L25*$B$18 -> 2917.7498
A28: – Dotations | C28: =C25*$B$19 -> 627.82978 | D28: =D25*$B$19 -> 643.52552 | E28: =E25*$B$19 -> 659.61366 | F28: =F25*$B$19 -> 676.104 | G28: =G25*$B$19 -> 693.0066 | H28: =H25*$B$19 -> 710.33177 | I28: =I25*$B$19 -> 728.09006 | J28: =J25*$B$19 -> 746.29231 | ... L28: =L25*$B$19 -> 784.07336
A29: EBIT | C29: =C27-C28 -> 1708.4952 | D29: =D27-D28 -> 1751.2076 | E29: =E27-E28 -> 1794.9878 | F29: =F27-F28 -> 1839.8625 | G29: =G27-G28 -> 1885.859 | H29: =H27-H28 -> 1933.0055 | I29: =I27-I28 -> 1981.3307 | J29: =J27-J28 -> 2030.8639 | ... L29: =L27-L28 -> 2133.6764
A30: – Impôt | C30: =MAX(C29,0)*$B$7 -> 497.17211 | D30: =MAX(D29,0)*$B$7 -> 509.60141 | E30: =MAX(E29,0)*$B$7 -> 522.34145 | F30: =MAX(F29,0)*$B$7 -> 535.39998 | G30: =MAX(G29,0)*$B$7 -> 548.78498 | H30: =MAX(H29,0)*$B$7 -> 562.50461 | I30: =MAX(I29,0)*$B$7 -> 576.56722 | J30: =MAX(J29,0)*$B$7 -> 590.9814 | ... L30: =MAX(L29,0)*$B$7 -> 620.89984
A31: NOPAT | C31: =C29-C30 -> 1211.3231 | D31: =D29-D30 -> 1241.6062 | E31: =E29-E30 -> 1272.6463 | F31: =F29-F30 -> 1304.4625 | G31: =G29-G30 -> 1337.0741 | H31: =H29-H30 -> 1370.5009 | I31: =I29-I30 -> 1404.7634 | J31: =J29-J30 -> 1439.8825 | ... L31: =L29-L30 -> 1512.7766
A32: + Dotations | C32: =C28 -> 627.82978 | D32: =D28 -> 643.52552 | E32: =E28 -> 659.61366 | F32: =F28 -> 676.104 | G32: =G28 -> 693.0066 | H32: =H28 -> 710.33177 | I32: =I28 -> 728.09006 | J32: =J28 -> 746.29231 | ... L32: =L28 -> 784.07336
A33: – Capex et loyers | C33: =C25*$B$20 -> 273.33877 | D33: =D25*$B$20 -> 280.17224 | E33: =E25*$B$20 -> 287.17654 | F33: =F25*$B$20 -> 294.35596 | G33: =G25*$B$20 -> 301.71486 | H33: =H25*$B$20 -> 309.25773 | I33: =I25*$B$20 -> 316.98917 | J33: =J25*$B$20 -> 324.9139 | ... L33: =L25*$B$20 -> 341.36267
A34: + BFR (encaissement) | C34: =(C25-B25)*$B$21 -> 0 | D34: =(D25-C25)*$B$21 -> 0 | E34: =(E25-D25)*$B$21 -> 0 | F34: =(F25-E25)*$B$21 -> 0 | G34: =(G25-F25)*$B$21 -> 0 | H34: =(H25-G25)*$B$21 -> 0 | I34: =(I25-H25)*$B$21 -> 0 | J34: =(J25-I25)*$B$21 -> 0 | ... L34: =(L25-K25)*$B$21 -> 0
A35: FCFF | C35: =C31+C32-C33+C34 -> 1565.8141 | D35: =D31+D32-D33+D34 -> 1604.9595 | E35: =E31+E32-E33+E34 -> 1645.0835 | F35: =F31+F32-F33+F34 -> 1686.2105 | G35: =G31+G32-G33+G34 -> 1728.3658 | H35: =H31+H32-H33+H34 -> 1771.575 | I35: =I31+I32-I33+I34 -> 1815.8643 | J35: =J31+J32-J33+J34 -> 1861.2609 | ... L35: =L31+L32-L33+L34 -> 1955.4873
A36: Période (années) | C36: 1 | D36: 2 | E36: 3 | F36: 4 | G36: 5 | H36: 6 | I36: 7 | J36: 8 | K36: 9 | L36: 10
A37: Facteur d'actualisation | C37: =1/(1+$B$13)^C36 -> 0.94706953 | D37: =1/(1+$B$13)^D36 -> 0.8969407 | E37: =1/(1+$B$13)^E36 -> 0.84946521 | F37: =1/(1+$B$13)^F36 -> 0.80450262 | G37: =1/(1+$B$13)^G36 -> 0.76191992 | H37: =1/(1+$B$13)^H36 -> 0.72159114 | I37: =1/(1+$B$13)^I36 -> 0.68339699 | J37: =1/(1+$B$13)^J36 -> 0.64722447 | ... L37: =1/(1+$B$13)^L36 -> 0.58052197
A38: FCFF actualisé | C38: =C35*C37 -> 1482.9348 | D38: =D35*D37 -> 1439.5535 | E38: =E35*E37 -> 1397.4412 | F38: =F35*F37 -> 1356.5608 | G38: =G35*G37 -> 1316.8763 | H38: =H35*H37 -> 1278.3528 | I38: =I35*I37 -> 1240.9562 | J38: =J35*J37 -> 1204.6536 | ... L38: =L35*L37 -> 1135.2033
A41: VALORISATION | B41: Valeur
A42: Somme des FCFF actualisés (jusqu'à l'échéance) | B42: =SUM(C38:L38) -> 13021.946
A43: VALEUR D'ENTREPRISE | B43: =B42 -> 13021.946 | C43: égale à la somme des FCFF : pas de valeur terminale car l'ouvrage revient à l'État
A44: VE / EBITDA 2025 | B44: =B43/B27 -> 5.7038745

Sheet Autres concessions
A1: Autres concessions, DCF jusqu'en 2040 puis annuité jusqu'à l'échéance
A3: COÛT DU CAPITAL | B3: Valeur
A4: Taux sans risque | B4: =Hypothèses!B5 -> 0.04
A5: Bêta désendetté (βu) | B5: 0.54 | C5: Damodaran Europe, Transportation
A6: D/E cible | B6: ='Eiffarie (APRR-AREA-Aliaé)'!B6 -> 1.2105018 | C6: Même structure financière que Eiffarie car concession matures comparables
A7: Taux d'impôt | B7: =Hypothèses!B7 -> 0.268
A8: Bêta réendetté | B8: =B5*(1+(1-B7)*B6) -> 1.0184871
A9: Prime de risque | B9: =Hypothèses!B6 -> 0.0494
A10: Coût des capitaux propres | B10: =B4+B8*B9 -> 0.090313265
A11: Coût de la dette avant impôt (Kd) | B11: =Hypothèses!B5+Hypothèses!B26 -> 0.048 | C11: Rf + spread (Hypothèses!B26)
A12: E/V | B12: =1/(1+B6) -> 0.45238598
A13: WACC | B13: =B12*B10+(1-B12)*B11*(1-B7) -> 0.060097421
A15: HYPOTHESES | B15: Valeur
A16: CA 2025 | B16: =Données!$B$26-'Eiffarie (APRR-AREA-Aliaé)'!B17 -> 738.3 | C16: CA Concessions (3 978, DEU) - CA Eiffarie = résiduel
A17: Marge d'EBITDA | B17: =B21/B16 -> 0.51469592 | C17: Marge observée 2025 du résiduel (EBITDA / CA), maintenue constante
A18: Dotations (% du CA) | B18: ='Eiffarie (APRR-AREA-Aliaé)'!B19 -> 0.18906592 | C18: Hypothèse : mêmes actifs que Eiffarie => même taux de dotations (taux APRR réel)
A19: Capex + loyers (% du CA) | B19: ='Eiffarie (APRR-AREA-Aliaé)'!B20 -> 0.082313785 | C19: Hypothèse : même taux de capex que Eiffarie (taux APRR réel)
A20: BFR encaissé (% de la hausse du CA) | B20: 0 | C20: Hypothèse idem que Eiffarie, BFR négligeable
A21: EBITDA 2025 (réel) | B21: =Données!$B$70-'Eiffarie (APRR-AREA-Aliaé)'!B22 -> 380 | C21: EBITDA Concessions (ROC 1 712 + dotations 951 = 2 663) - EBITDA Eiffarie = résiduel
A23: M€ | B23: 2025 | C23: 2026 | D23: 2027 | E23: 2028 | F23: 2029 | G23: 2030 | H23: 2031 | I23: 2032 | J23: 2033 | K23: 2034 | L23: 2035 | M23: 2036 | N23: 2037 | O23: 2038 | P23: 2039 | Q23: 2040
A24: Chiffre d'affaires | B24: =B16 -> 738.3 | C24: =B24*(1+C25) -> 756.7575 | D24: =C24*(1+D25) -> 775.67644 | E24: =D24*(1+E25) -> 795.06835 | F24: =E24*(1+F25) -> 814.94506 | G24: =F24*(1+G25) -> 835.31868 | H24: =G24*(1+H25) -> 856.20165 | I24: =H24*(1+I25) -> 877.60669 | J24: =I24*(1+J25) -> 899.54686 | ... Q24: =P24*(1+Q25) -> 1069.2785
A25: Croissance | C25: 0.025 | D25: 0.025 | E25: 0.025 | F25: 0.025 | G25: 0.025 | H25: 0.025 | I25: 0.025 | J25: 0.025 | K25: 0.025 | L25: 0.025 | M25: 0.025 | N25: 0.025 | O25: 0.025 | P25: 0.025 | Q25: 0.025
A26: EBITDA | B26: =B21 -> 380 | C26: =C24*$B$17 -> 389.5 | D26: =D24*$B$17 -> 399.2375 | E26: =E24*$B$17 -> 409.21844 | F26: =F24*$B$17 -> 419.4489 | G26: =G24*$B$17 -> 429.93512 | H26: =H24*$B$17 -> 440.6835 | I26: =I24*$B$17 -> 451.70059 | J26: =J24*$B$17 -> 462.9931 | ... Q26: =Q24*$B$17 -> 550.3533
A27: – Dotations | C27: =C24*$B$18 -> 143.07705 | D27: =D24*$B$18 -> 146.65398 | E27: =E24*$B$18 -> 150.32033 | F27: =F24*$B$18 -> 154.07834 | G27: =G24*$B$18 -> 157.93029 | H27: =H24*$B$18 -> 161.87855 | I27: =I24*$B$18 -> 165.92552 | J27: =J24*$B$18 -> 170.07365 | ... Q27: =Q24*$B$18 -> 202.16413
A28: EBIT | C28: =C26-C27 -> 246.42295 | D28: =D26-D27 -> 252.58352 | E28: =E26-E27 -> 258.89811 | F28: =F26-F27 -> 265.37056 | G28: =G26-G27 -> 272.00483 | H28: =H26-H27 -> 278.80495 | I28: =I26-I27 -> 285.77507 | J28: =J26-J27 -> 292.91945 | ... Q28: =Q26-Q27 -> 348.18917
A29: – Impôt | C29: =MAX(C28,0)*$B$7 -> 66.04135 | D29: =MAX(D28,0)*$B$7 -> 67.692384 | E29: =MAX(E28,0)*$B$7 -> 69.384693 | F29: =MAX(F28,0)*$B$7 -> 71.119311 | G29: =MAX(G28,0)*$B$7 -> 72.897293 | H29: =MAX(H28,0)*$B$7 -> 74.719726 | I29: =MAX(I28,0)*$B$7 -> 76.587719 | J29: =MAX(J28,0)*$B$7 -> 78.502412 | ... Q29: =MAX(Q28,0)*$B$7 -> 93.314699
A30: NOPAT | C30: =C28-C29 -> 180.3816 | D30: =D28-D29 -> 184.89114 | E30: =E28-E29 -> 189.51342 | F30: =F28-F29 -> 194.25125 | G30: =G28-G29 -> 199.10753 | H30: =H28-H29 -> 204.08522 | I30: =I28-I29 -> 209.18735 | J30: =J28-J29 -> 214.41704 | ... Q30: =Q28-Q29 -> 254.87448
A31: + Dotations | C31: =C27 -> 143.07705 | D31: =D27 -> 146.65398 | E31: =E27 -> 150.32033 | F31: =F27 -> 154.07834 | G31: =G27 -> 157.93029 | H31: =H27 -> 161.87855 | I31: =I27 -> 165.92552 | J31: =J27 -> 170.07365 | ... Q31: =Q27 -> 202.16413
A32: – Capex et loyers | C32: =C24*$B$19 -> 62.291574 | D32: =D24*$B$19 -> 63.848863 | E32: =E24*$B$19 -> 65.445085 | F32: =F24*$B$19 -> 67.081212 | G32: =G24*$B$19 -> 68.758242 | H32: =H24*$B$19 -> 70.477198 | I32: =I24*$B$19 -> 72.239128 | J32: =J24*$B$19 -> 74.045107 | ... Q32: =Q24*$B$19 -> 88.016363
A33: + BFR (encaissement) | C33: =(C24-B24)*$B$20 -> 0 | D33: =(D24-C24)*$B$20 -> 0 | E33: =(E24-D24)*$B$20 -> 0 | F33: =(F24-E24)*$B$20 -> 0 | G33: =(G24-F24)*$B$20 -> 0 | H33: =(H24-G24)*$B$20 -> 0 | I33: =(I24-H24)*$B$20 -> 0 | J33: =(J24-I24)*$B$20 -> 0 | ... Q33: =(Q24-P24)*$B$20 -> 0
A34: FCFF | C34: =C30+C31-C32+C33 -> 261.16708 | D34: =D30+D31-D32+D33 -> 267.69625 | E34: =E30+E31-E32+E33 -> 274.38866 | F34: =F30+F31-F32+F33 -> 281.24838 | G34: =G30+G31-G32+G33 -> 288.27959 | H34: =H30+H31-H32+H33 -> 295.48657 | I34: =I30+I31-I32+I33 -> 302.87374 | J34: =J30+J31-J32+J33 -> 310.44558 | ... Q34: =Q30+Q31-Q32+Q33 -> 369.02224
A35: Période (années) | C35: 1 | D35: 2 | E35: 3 | F35: 4 | G35: 5 | H35: 6 | I35: 7 | J35: 8 | K35: 9 | L35: 10 | M35: 11 | N35: 12 | O35: 13 | P35: 14 | Q35: 15
A36: Facteur d'actualisation | C36: =1/(1+$B$13)^C35 -> 0.94330953 | D36: =1/(1+$B$13)^D35 -> 0.88983287 | E36: =1/(1+$B$13)^E35 -> 0.83938783 | F36: =1/(1+$B$13)^F35 -> 0.79180254 | G36: =1/(1+$B$13)^G35 -> 0.74691488 | H36: =1/(1+$B$13)^H35 -> 0.70457192 | I36: =1/(1+$B$13)^I35 -> 0.66462941 | J36: =1/(1+$B$13)^J35 -> 0.62695126 | ... Q36: =1/(1+$B$13)^Q35 -> 0.41669024
A37: FCFF actualisé | C37: =C34*C36 -> 246.36139 | D37: =D34*D36 -> 238.20492 | E37: =E34*E36 -> 230.3185 | F37: =F34*F36 -> 222.69318 | G37: =G34*G36 -> 215.32031 | H37: =H34*H36 -> 208.19154 | I37: =I34*I36 -> 201.29879 | J37: =J34*J36 -> 194.63425 | ... Q37: =Q34*Q36 -> 153.76797
A40: VALORISATION | B40: Valeur
A41: Somme des FCFF actualisés (jusqu'en 2040) | B41: =SUM(C37:Q37) -> 2950.4991
A42: Croissance après la dernière année projetée | B42: 0.009
A43: Échéance moyenne des concessions | B43: 2060 | C43: Moyenne indicative (A'liénor 2066, Adelac 2060, Millau 2079, Sénégal 2044 etc)
A44: Années restantes après 2040 | B44: =B43-2040 -> 20
A45: Valeur actualisée de l'annuité après 2040 | B45: =IF(B44>0,Q34*(1+B42)/(B13-B42)*(1-((1+B42)/(1+B13))^B44)*Q36,0) -> 1905.9059
...

Sheet Multiples
A1: Évaluation par les multiples avec comparables cotés
A2: M€ sauf Skanska en MSEK ; Cours du 09/10/2026 ; Dette nette avec dettes de location et EBITDA avant loyers (IFRS 16)
A3: Colonne « Retenu » : 1 = inclus dans les statistiques, 0 = exclu
N4: seulement si retenu
A5: Société | B5: Retenu | C5: Cours au 09/10/2026 | D5: Nb actions (M) | E5: Capitalisation | F5: Dette nette | G5: Minoritaires | H5: MEE | I5: VE | J5: CA 2025 | K5: EBITDA 2025 | L5: EBIT 2025 | M5: Résultat net pdg | N5: VE/CA | O5: VE/EBITDA | P5: VE/EBIT | Q5: PER | R5: Source / remarque (voir le détail des données)
A6: Vinci | B6: 1 | C6: 107.05 | D6: =E48-F48 -> 555.08962 | E6: =C6*D6 -> 59422.344 | F6: =B48+C48+D48 -> 21924 | G6: 3576 | H6: 1995 | I6: =E6+F6+G6-H6 -> 82927.344 | J6: 74599 | K6: 13507 | L6: 9558 | M6: 4903 | N6: =IF($B6=1,I6/J6,"") -> 1.1116415 | O6: =IF($B6=1,I6/K6,"") -> 6.1395827 | P6: =IF($B6=1,I6/L6,"") -> 8.6762235 | Q6: =IF($B6=1,E6/M6,"") -> 12.119589 | R6: Rapport Vinci 2025 / Dette nette : endettement financier net 19 075 + dettes de location 2 849 (non courantes 2 112 + courantes 737)
A7: Bouygues | B7: 1 | C7: 40.3 | D7: =E49-F49 -> 384.28808 | E7: =C7*D7 -> 15486.809 | F7: =B49+C49+D49 -> 7623 | G7: 1815 | H7: 1614 | I7: =E7+F7+G7-H7 -> 23310.809 | J7: 56877 | K7: =G49+H49 -> 5579 | L7: 2555 | M7: 1138 | N7: =IF($B7=1,I7/J7,"") -> 0.40984597 | O7: =IF($B7=1,I7/K7,"") -> 4.1783132 | P7: =IF($B7=1,I7/L7,"") -> 9.1236045 | Q7: =IF($B7=1,E7/M7,"") -> 13.608796 | R7: Rapport Bouygues 2025 / Dette nette 4 204 + obligations locatives 3 419 (non courantes 2 847 + courantes 572). EBITDA après loyers 5 124 + remboursement des obligations locatives 455
A8: Hochtief | B8: 1 | C8: 389.8 | D8: =I50/J50 -> 75.229358 | E8: =C8*D8 -> 29324.404 | F8: =B50+C50+D50 -> 744 | G8: 122 | H8: 2233 | I8: =E8+F8+G8-H8 -> 27957.404 | J8: 38237 | K8: 2215 | L8: 1544 | M8: 902 | N8: =IF($B8=1,I8/J8,"") -> 0.73116101 | O8: =IF($B8=1,I8/K8,"") -> 12.621853 | P8: =IF($B8=1,I8/L8,"") -> 18.107127 | Q8: =IF($B8=1,E8/M8,"") -> 32.510425 | R8: Présentation FY2025 Hochtief / Dette nette 97 + dettes de location 647 (423 + 224). Nb d'actions déduit du BPA nominal (902 / 11,99). RETENU : pair direct des Travaux (BTP/construction international, 5e comparable coté pour avoir un échantillon suffisant). Limite : sa participation dans Abertis (MEE, 2 233 à la valeur comptable) est déduite de la VE et hors EBITDA, donc les multiples sont élevés (PER ≈ 32x) et tirent la borne haute des fourchettes.
A9: Strabag | B9: 1 | C9: 102.2 | D9: 115.443 | E9: =C9*D9 -> 11798.275 | F9: -3518 | G9: 21.1 | H9: 595.3 | I9: =E9+F9+G9-H9 -> 7706.0746 | J9: 18714 | K9: 1883 | L9: 1247 | M9: 916.3 | N9: =IF($B9=1,I9/J9,"") -> 0.41178127 | O9: =IF($B9=1,I9/K9,"") -> 4.0924454 | P9: =IF($B9=1,I9/L9,"") -> 6.1796909 | Q9: =IF($B9=1,E9/M9,"") -> 12.875995 | R9: Rapport Strabag 2025, tableau « Calculation of net debt » / Trésorerie nette publiée 3 518 : inclut les dettes de location (368), les provisions de retraite et d'indemnités de départ (+376) et exclut les dettes sans recours de grands projets (−399)
A10: Skanska | B10: 1 | C10: 263.8 | D10: =E51-F51 -> 413.96773 | E10: =C10*D10 -> 109204.69 | F10: =B51+C51+D51 -> -5295 | G10: 192 | H10: 2318 | I10: =E10+F10+G10-H10 -> 101783.69 | J10: 179291 | K10: 10071 | L10: 7241 | M10: 6295 | N10: =IF($B10=1,I10/J10,"") -> 0.56770104 | O10: =IF($B10=1,I10/K10,"") -> 10.106612 | P10: =IF($B10=1,I10/L10,"") -> 14.056579 | Q10: =IF($B10=1,E10/M10,"") -> 17.347846 | R10: Rapport Skanska 2025 (en MSEK) / Trésorerie nette ajustée 11 504 − dettes de location 6 209. EBITDA = Zonebourse car non publié
A11: Ferrovial | B11: 0 | C11: 44.6 | D11: 733.755 | E11: =C11*D11 -> 32725.473 | F11: 5893 | G11: 1757 | H11: 3955 | I11: =E11+F11+G11-H11 -> 36420.473 | J11: 9627 | K11: 1457 | L11: 967 | M11: 888 | N11: =IF($B11=1,I11/J11,"") | O11: =IF($B11=1,I11/K11,"") | P11: =IF($B11=1,I11/L11,"") | Q11: =IF($B11=1,E11/M11,"") | R11: EXCLU : l'EBITDA ajusté ne comprend pas les sociétés mises en équivalence, multiples non comparables
A13: Statistiques (comparables retenus)
A14: Minimum | N14: =MIN(N$6:N$11) -> 0.40984597 | O14: =MIN(O$6:O$11) -> 4.0924454 | P14: =MIN(P$6:P$11) -> 6.1796909 | Q14: =MIN(Q$6:Q$11) -> 12.119589
A15: 1er quartile | N15: =QUARTILE(N$6:N$11,1) -> 0.41178127 | O15: =QUARTILE(O$6:O$11,1) -> 4.1783132 | P15: =QUARTILE(P$6:P$11,1) -> 8.6762235 | Q15: =QUARTILE(Q$6:Q$11,1) -> 12.875995
A16: Médiane | N16: =MEDIAN(N$6:N$11) -> 0.56770104 | O16: =MEDIAN(O$6:O$11) -> 6.1395827 | P16: =MEDIAN(P$6:P$11) -> 9.1236045 | Q16: =MEDIAN(Q$6:Q$11) -> 13.608796
A17: Moyenne | N17: =AVERAGE(N6:N11) -> 0.64642616 | O17: =AVERAGE(O6:O11) -> 7.4277612 | P17: =AVERAGE(P6:P11) -> 11.228645 | Q17: =AVERAGE(Q6:Q11) -> 17.69253
A18: 3e quartile | N18: =QUARTILE(N$6:N$11,3) -> 0.73116101 | O18: =QUARTILE(O$6:O$11,3) -> 10.106612 | P18: =QUARTILE(P$6:P$11,3) -> 14.056579 | Q18: =QUARTILE(Q$6:Q$11,3) -> 17.347846
A19: Maximum | N19: =MAX(N$6:N$11) -> 1.1116415 | O19: =MAX(O$6:O$11) -> 12.621853 | P19: =MAX(P$6:P$11) -> 18.107127 | Q19: =MAX(Q$6:Q$11) -> 32.510425
A21: Eiffage (cible)
A22: Cours | B22: =Hypothèses!B9 -> 98.72
A23: Capitalisation | B23: =Hypothèses!B11 -> 9386.4698
A24: Dette nette avec loyers (DEU 2025) | B24: =Données!$B$35 -> 9905
A25: Minoritaires (résultat 445 × PER de marché) | B25: =Données!$B$36*Hypothèses!B13 -> 4105.6449
A26: MEE (Getlink au marché) | B26: =Hypothèses!B20 -> 3093.9162
A27: VE de marché | B27: =B23+B24+B25-B26 -> 20303.198
A28: EBITDA 2025 | B28: =Données!$B$19 -> 4394
A29: EBIT 2025 | B29: =Données!$B$20 -> 2545
A30: BPA dilué (€) | B30: =Hypothèses!B12 -> 10.7
A31: VE/EBITDA de marché | B31: =B27/B28 -> 4.6206642
A32: VE/EBIT de marché | B32: =B27/B29 -> 7.9776811
A33: PER de marché | B33: =B22/B30 -> 9.2261682
A36: Valeur implicite par action (€) | B36: Agrégat | C36: Mult. bas (Q1) | D36: Mult. médian | E36: Mult. haut (Q3) | F36: € bas | G36: € médian | H36: € haut
A37: VE / EBITDA 2025 | B37: =B28 -> 4394 | C37: =O15 -> 4.1783132 | D37: =O16 -> 6.1395827 | E37: =O18 -> 10.106612 | F37: =(C37*$B37-$B$24-$B$25+$B$26)/Hypothèses!$B$10 -> 78.277694 | G37: =(D37*$B37-$B$24-$B$25+$B$26)/Hypothèses!$B$10 -> 168.91358 | H37: =(E37*$B37-$B$24-$B$25+$B$26)/Hypothèses!$B$10 -> 352.24137
A38: VE / EBIT 2025 | B38: =B29 -> 2545 | C38: =P15 -> 8.6762235 | D38: =P16 -> 9.1236045 | E38: =P18 -> 14.056579 | F38: =(C38*$B38-$B$24-$B$25+$B$26)/Hypothèses!$B$10 -> 117.41749 | G38: =(D38*$B38-$B$24-$B$25+$B$26)/Hypothèses!$B$10 -> 129.39229 | H38: =(E38*$B38-$B$24-$B$25+$B$26)/Hypothèses!$B$10 -> 261.43047
A39: PER 2025 | B39: =B30 -> 10.7 | C39: =Q15 -> 12.875995 | D39: =Q16 -> 13.608796 | E39: =Q18 -> 17.347846 | F39: =C39*$B39 -> 137.77315 | G39: =D39*$B39 -> 145.61411 | H39: =E39*$B39 -> 185.62195
A41: Valeur par action = (multiple × agrégat Eiffage - dette nette - minoritaires + MEE) / nombre d'actions.
A42: Méthode PER : multiple × BPA dilué
A46: Détail des données brutes saisies
A47: Société | B47: Dette nette : composante 1 | C47: Dettes de location non courantes : composante 2 | D47: Dettes de location courantes : composante 3 | E47: Actions émises (M) | F47: Actions auto-détenues (M) | G47: EBITDA : composante 1 | H47: EBITDA : composante 2 | I47: Résultat net pdg | J47: BPA nominal (€)
A48: Vinci | B48: 19075 | C48: 2112 | D48: 737 | E48: 581.81683 | F48: 26.727207
...
